Workbook

Sheet INCIDENCIAS
A1: SEMANA | B1: TIENDA | C1: FECHA | D1: SEMANA | E1: AREA | F1: PRODUCTO | G1: MARCA | H1: CANT | I1: P. VENTA | J1: TOTAL | K1: TIPO INCIDENCIA | L1: PERSONAL TIENDA | M1: DATOS INVOLUCRADOS | N1: DNI | O1: OBSERVACIONES
A2: Semana | B2: Tienda | C2: Fecha | D2: Semana2 | E2: Área | F2: Producto | G2: Marca | H2: Cantidad | I2: P. Venta | J2: Total | K2: Tipo Incidencia | L2: Personal Tienda | M2: Datos Involucrado | N2: DNI | O2: Observaciones
A3: Del 01 al 30 Abril
B4: MARINA | C4: 46113 | E4: TEXTIL | F4: Polo m/c | G4: DISNEY LACOSTE | H4: 2 | I4: 34.90 + 99.00 | J4: 133.9 | K4: ROBO FRUSTRADO | L4: SRTA GREYDI | M4: SIN DATOS MUJER | N4: 0
B5: MARINA | C5: 46113 | D5: =WEEKNUM(INCIDENCIAS!$C5) -> 14 | E5: OTROS | F5: BILLETERA | H5: 1 | I5: 14 | J5: =INCIDENCIAS!$H5*INCIDENCIAS!$I5 -> 14 | K5: ROBO FRUSTRADO | L5: SRTA GREYDI | M5: SIN DATOS MUJER | N5: 0
B6: MARINA | C6: 46115 | D6: =WEEKNUM(INCIDENCIAS!$C6) -> 14 | E6: TEXTIL | F6: POLAR | G6: COACH | H6: 1 | I6: 170 | J6: 170 | K6: ROBO | L6: SRTA GREYDI | M6: 2 MENORES DE EDAD | N6: 0
B7: AYACUCHO | C7: 46120 | D7: =WEEKNUM(INCIDENCIAS!$C7) -> 15 | E7: CALZADO | F7: ZAPATILLA | G7: ADIDAS | H7: 2 | I7: 159 + 169 | J7: 328 | K7: ROBO | L7: SEG ANIBAL | M7: SIN DATOS V Y M | N7: 0
B8: EMANCIPACIÓN | C8: 46120 | D8: =WEEKNUM(INCIDENCIAS!$C8) -> 15 | E8: CALZADO | F8: ZAPATILLA | G8: ECKKO | H8: 1 | I8: 89 | J8: 89 | K8: ROBO | M8: SIN DATOS VARON | N8: 0
B9: MARINA | C9: 46121 | D9: 16 | E9: CALZADO | F9: ZAPATILLA | G9: UNDER ARMOUR | H9: 1 | I9: 139 | J9: 139 | K9: ROBO FRUSTADO | L9: TRABAJO EN CONJUNTO | M9: SIN DATOS VARON | N9: 0
B10: PUENTE PIEDRA | C10: 46125 | D10: 16 | E10: CALZADO | F10: ZAPATILLA | G10: ADIDAS | H10: 1 | I10: 249 | J10: =INCIDENCIAS!$H10*INCIDENCIAS!$I10 -> 249 | K10: ROBO | L10: COLABORADORES | M10: SIN DATOS | N10: 0
B11: MARINA | C11: 46125 | D11: =WEEKNUM(INCIDENCIAS!$C11) -> 16 | E11: TEXTIL | F11: Polo m/c | G11: LACOSTE | H11: 1 | I11: 99 | J11: =INCIDENCIAS!$H11*INCIDENCIAS!$I11 -> 99 | K11: FALTA
B12: ANGAMOS | C12: 46126 | D12: =WEEKNUM(INCIDENCIAS!$C12) -> 16 | E12: OTROS | F12: TARJETA DE MEMORIA 128GH | G12: MEMORY CARD | H12: 1 | I12: 38 | J12: =INCIDENCIAS!$H12*INCIDENCIAS!$I12 -> 38 | K12: ROBO | L12: CAJERA FELICINDA | M12: 0 | N12: 0
B13: EMANCIPACIÓN | C13: 46126 | D13: =WEEKNUM(INCIDENCIAS!$C13) -> 16 | E13: TEXTIL | F13: Polo m/c | G13: LACOSTE | H13: 1 | I13: 79 | J13: =INCIDENCIAS!$H13*INCIDENCIAS!$I13 -> 79 | K13: ROBO FRUSTRADO | L13: SEG ONASIS | M13: JUAN CARLOS OCHOA GUERRA | N13: 7501310
B14: EMANCIPACIÓN | C14: 46128 | D14: =WEEKNUM(INCIDENCIAS!$C14) -> 16 | E14: CALZADO | F14: ZAPATILLAS | G14: MARCA | H14: 1 | I14: 149 | J14: =INCIDENCIAS!$H14*INCIDENCIAS!$I14 -> 149 | K14: ROBO FRUSTRADO | L14: SEG ONASIS | M14: SIN DATOS | N14: 0
B15: MARINA | C15: 46134 | D15: =WEEKNUM(INCIDENCIAS!$C15) -> 17 | E15: Textil | F15: POLO | G15: ARMANI | H15: 1 | I15: 65 | J15: =INCIDENCIAS!$H15*INCIDENCIAS!$I15 -> 65 | K15: ROBO FRUSTADO | L15: ADM DAYETZA | M15: MANUEL | N15: 0
B16: PUENTE PIEDRA | C16: 46134 | D16: =WEEKNUM(INCIDENCIAS!$C16) -> 17 | E16: CALZADO | F16: ZAPATILLA | G16: ADIDAS | H16: 1 | I16: 159 | J16: =INCIDENCIAS!$H16*INCIDENCIAS!$I16 -> 159 | K16: ROBO | L16: SEG PEREYRA | M16: PAREJA | N16: 0
B17: INDEPENDENCIA | C17: 46136 | D17: =WEEKNUM(INCIDENCIAS!$C17) -> 17 | E17: TEXTIL | F17: POLO | G17: BOSS | H17: 3 | I17: 89.9 + 79 + 85 | J17: 253.9 | K17: ROBO FRUSTADO | L17: VEND NICOL VASQUEZ | M17: 3 JOVENES MENOR EDAD | N17: 0
B18: CALLAO | C18: 46136 | D18: =WEEKNUM(INCIDENCIAS!$C18) -> 17 | E18: CALZADO | F18: ZAPATILLA | G18: ECKO | H18: 1 | I18: 109 | J18: 109 | K18: ROBO | L18: VENDEDOR | M18: 1 VARON | N18: 0
B19: ALFONSO UGARTE | C19: 46138 | D19: =WEEKNUM(INCIDENCIAS!$C19) -> 18 | E19: CALZADO | F19: ZAPATILLA | G19: ECKO | H19: 1 | I19: 89 | J19: =INCIDENCIAS!$H19*INCIDENCIAS!$I19 -> 89 | K19: ROBO FRUSTADO | L19: SEG FRANCO | M19: SIN DATOS VARON | N19: 0
B20: MARINA | C20: 46138 | D20: =WEEKNUM(INCIDENCIAS!$C20) -> 18 | E20: TEXTIL | F20: LEGGING | G20: ADIDAS | H20: 1 | I20: 89.9 | J20: =INCIDENCIAS!$H20*INCIDENCIAS!$I20 -> 89.9 | K20: ROBO FRUSTRADO | L20: SEG YULEIDYS | M20: 2 FEMINAS | N20: 0
B21: MARINA | C21: 46138 | D21: =WEEKNUM(INCIDENCIAS!$C21) -> 18 | E21: OTROS | F21: PERFUME | G21: DIAVOLO EDT | H21: 1 | I21: 35 | J21: =INCIDENCIAS!$H21*INCIDENCIAS!$I21 -> 35 | K21: ROBO | L21: SEG YULEIDYS | M21: 1 VARON | N21: 0
B22: ANGAMOS | C22: 46141 | D22: =WEEKNUM(INCIDENCIAS!$C22) -> 18 | E22: CALZADO | F22: ZAPATILLAS | G22: ADIDAS | H22: 1 | I22: 109 | J22: =INCIDENCIAS!$H22*INCIDENCIAS!$I22 -> 109 | K22: ROBO | L22: OSCAR | M22: 1 VARON | N22: 0
A24: DEL 01 AL 31 MAYO | B24: ANGAMOS | C24: 46144 | D24: 1 | E24: TEXTIL | F24: POLO | G24: PSYCHO BUNNY | H24: 2 | I24: 65.00 + 65.00 | J24: 130 | K24: ROBO FRUSTRADO | L24: SEG MARCOS TENORIO | M24: 1 FEMINA | N24: 0
B25: MARINA | C25: 46148 | D25: =WEEKNUM(INCIDENCIAS!$C25) -> 19 | E25: TEXTIL | F25: SHORT | G25: NKG | H25: 5 | I25: 99.9 | J25: =INCIDENCIAS!$H25*INCIDENCIAS!$I25 -> 499.5 | K25: ROBO FRUSTRADO | L25: SEG YULEIDI | M25: 1 VARON | N25: 0
B26: MARINA | C26: 46148 | D26: =WEEKNUM(INCIDENCIAS!$C26) -> 19 | E26: TEXTIL | F26: POLO | G26: QUICKSILVER | H26: 2 | I26: 34.9 | J26: =INCIDENCIAS!$H26*INCIDENCIAS!$I26 -> 69.8 | K26: ROBO FRUSTRADO | L26: SEG YULEIDI | M26: 1 VARON | N26: 0
B27: MARINA | C27: 46148 | D27: =WEEKNUM(INCIDENCIAS!$C27) -> 19 | E27: TEXTIL | F27: POLO | G27: LACOSTE | H27: 1 | I27: 99 | J27: =INCIDENCIAS!$H27*INCIDENCIAS!$I27 -> 99 | K27: ROBO FRUSTRADO | L27: SEG YULEIDI | M27: 1 VARON | N27: 0
B28: EMANCIPACIÓN | C28: 46148 | D28: 19 | E28: CALZADO | F28: ZAPATILLA | G28: ADIDAS | H28: 1 | I28: 149 | J28: 149 | K28: ROBO FRUSTRADO | L28: SEG ONASIS | M28: 1 VARON | N28: 0
B29: AYACUCHO | C29: 46149 | D29: =WEEKNUM(INCIDENCIAS!$C29) -> 19 | E29: TEXTIL | F29: CASACA | G29: NKG | H29: 1 | I29: 189 | J29: =INCIDENCIAS!$H29*INCIDENCIAS!$I29 -> 189 | K29: ROBO FRUSTRADO | L29: SEG ANIBAL | M29: 1 VARON | N29: 0
B30: MARINA | C30: 46151 | D30: =WEEKNUM(INCIDENCIAS!$C30) -> 19 | E30: TEXTIL | F30: POLO CAMISERO | G30: LACOSTE | H30: 2 | I30: 99 | J30: =INCIDENCIAS!$H30*INCIDENCIAS!$I30 -> 198 | K30: ROBO FRUSTRADO | L30: ALMACENERO MOISES | M30: 2 VARONES | N30: 0
B31: ALFONSO UGARTE | C31: 46151 | D31: =WEEKNUM(INCIDENCIAS!$C31) -> 19 | E31: CALZADO | F31: ZAPATILLA | G31: NIKE | H31: 1 | I31: 389 | J31: =INCIDENCIAS!$H31*INCIDENCIAS!$I31 -> 389 | K31: ROBO | L31: NADIE | M31: 1 VARON | N31: 0
B32: ANGAMOS | C32: 46156 | D32: =WEEKNUM(INCIDENCIAS!$C32) -> 20 | E32: CALZADO | F32: ZAPATILLA | G32: AVENGERS | H32: 1 | I32: 69 | J32: =INCIDENCIAS!$H32*INCIDENCIAS!$I32 -> 69 | K32: ROBO | L32: SEG TENORIO | M32: 0 | N32: 0
B33: EMANCIPACIÓN | C33: 46158 | D33: =WEEKNUM(INCIDENCIAS!$C33) -> 20 | E33: TEXTIL | F33: CASACA | G33: MILK | H33: 1 | I33: 81 | J33: =INCIDENCIAS!$H33*INCIDENCIAS!$I33 -> 81 | K33: ROBO FRUSTADO | L33: SEG ONASIS | M33: 1 VARON | N33: 0
B34: MARINA | C34: 46158 | D34: =WEEKNUM(INCIDENCIAS!$C34) -> 20 | E34: TEXTIL | F34: SHORT | G34: EL CAPO | H34: 1 | I34: 39.9 | J34: =INCIDENCIAS!$H34*INCIDENCIAS!$I34 -> 39.9 | K34: ROBO FRUSTADO | L34: SEG LUIS GARCIA | M34: 1 VARON | N34: 0
B35: ARGENTINA | C35: 46162 | D35: =WEEKNUM(INCIDENCIAS!$C35) -> 21 | E35: CALZADO | F35: ZAPATILLA | G35: ADIDAS | H35: 1 | I35: 119 | J35: =INCIDENCIAS!$H35*INCIDENCIAS!$I35 -> 119 | K35: ROBO | L35: NADIE | M35: 0 | N35: 0
B36: ANGAMOS | C36: 46167 | D36: =WEEKNUM(INCIDENCIAS!$C36) -> 22 | E36: OTROS | F36: CREMA FACIAL | H36: 1 | I36: 60 | J36: =INCIDENCIAS!$H36*INCIDENCIAS!$I36 -> 60 | K36: ROBO | L36: NADIE | M36: 0 | N36: 0
B37: CALLAO | C37: 46170 | D37: =WEEKNUM(INCIDENCIAS!$C37) -> 22 | E37: CALZADO | F37: ZAPATILLA | G37: APOLO | H37: 1 | I37: 79 | J37: =INCIDENCIAS!$H37*INCIDENCIAS!$I37 -> 79 | K37: ROBO | L37: NADIE | M37: 0 | N37: 0
B38: TRUJILLO | C38: 46171 | D38: =WEEKNUM(INCIDENCIAS!$C38) -> 22 | E38: TEXTIL | F38: POLO | G38: PSYCHO BUNNY | H38: 1 | I38: 65 | J38: =INCIDENCIAS!$H38*INCIDENCIAS!$I38 -> 65 | K38: ROBO FRUSTADO | L38: SEG CESAR RUIZ | M38: 1 VARON | N38: 0
B39: TRUJILLO | C39: 46171 | D39: =WEEKNUM(INCIDENCIAS!$C39) -> 22 | E39: TEXTIL | F39: POLETA | G39: LACOSTE | H39: 1 | I39: 79 | J39: =INCIDENCIAS!$H39*INCIDENCIAS!$I39 -> 79 | K39: ROBO FRUSTADO | L39: SEG CESAR RUIZ | M39: 1 VARON | N39: 0
B40: CALLAO | C40: 46172 | D40: =WEEKNUM(INCIDENCIAS!$C40) -> 22 | E40: CALZADO | F40: ZAPATILLA | G40: THE CALLISTO | H40: 1 | I40: 99 | J40: =INCIDENCIAS!$H40*INCIDENCIAS!$I40 -> 99 | K40: ROBO | L40: NADIE | M40: 0 | N40: 0
B41: CALLAO | C41: 46172 | D41: =WEEKNUM(INCIDENCIAS!$C41) -> 22 | E41: TEXTIL | F41: PANTALON | G41: APACHE | H41: 1 | I41: 59.9 | J41: =INCIDENCIAS!$H41*INCIDENCIAS!$I41 -> 59.9 | K41: ROBO FRUSTADO | L41: ZONAL DAVID QUIJANO | M41: 1 VARON | N41: 0
...

Sheet tabla
A1: VALORIZADO DE ROBOS POR TIENDA | M1: VALORIZADO DE ROBOS POR SEMANA
A3: SUMA DE TOTAL | B3: ETIQUETAS DE COLUMNA | G3: SUMA DE TOTAL | H3: ETIQUETAS DE COLUMNA | M3: SUMA DE TOTAL | N3: ETIQUETAS DE COLUMNA
A4: ETIQUETAS DE FILA | B4: Mar | C4: Abr | D4: Total general | G4: ETIQUETAS DE FILA | H4: Mar | I4: Abr | J4: Total general | M4: ETIQUETAS DE FILA | N4: Mar | O4: Abr | P4: Total general
A5: MARINA | B5: 89.9 | C5: 119.7 | D5: 209.6 | G5: CALZADO | I5: 237 | J5: 237 | M5: DEL 06 al 12 ABRIL | N5: 89.9 | P5: 89.9
A6: AYACUCHO | C6: 108 | D6: 108 | G6: TEXTIL | H6: 89.9 | I6: 119.7 | J6: 209.6 | M6: (EN BANCO) | O6: 356.7 | P6: 356.7
A7: EMANCIPACIÓN | C7: 129 | D7: 129 | G7: TOTAL GENERAL | H7: 89.9 | I7: 356.7 | J7: 446.6 | M7: TOTAL GENERAL | N7: 89.9 | O7: 356.7 | P7: 446.6
A8: Total general | B8: 89.9 | C8: 356.7 | D8: 446.6

Sheet Lista
A1: Tienda | C1: Area
A2: MARINA | C2: TEXTIL
A3: EMANCIPACIÓN | C3: CALZADO
A4: INDEPENDENCIA | C4: OTROS
A5: ANGAMOS
A6: TRUJILLO
A7: AYACUCHO
A8: PUENTE PIEDRA
A9: TUMBES
A10: ARAMBURU
A11: ALFONSO UGARTE
A12: PERSHING
A13: CALLAO
A14: ALIPIO
A15: CHORRILLOS
A16: JR UNION N°797
... A18: ARGENTINA

Sheet TRÁFICO DE CLIENTES
C1: CONTEO DE CLIENTES SEGURIDAD - 02 AL 08 DE MARZO 2026
A3: TIENDAS | B3: LUNES 2 | C3: MARTES 3 | D3: MIERCOLES 4 | E3: JUEVES 5 | F3: VIERNES 6 | G3: SABADO 7 | H3: DOMINGO 8 | I3: TOTAL
A4: AYACUCHO | B4: S/N | C4: S/N | D4: S/N | E4: S/N | F4: S/N | G4: S/N | H4: S/N | I4: S/N
A5: ANGAMOS | B5: 209 | C5: 177 | D5: 167 | E5: 254 | F5: 232 | G5: 285 | H5: 309 | I5: 1724
A6: TUMBES | B6: S/N | C6: S/N | D6: S/N | E6: S/N | F6: S/N | G6: S/N | H6: S/N | I6: S/N
A7: EMANCIPACION | B7: 221 | C7: 190 | D7: 255 | E7: 222 | F7: 200 | G7: 276 | H7: 230 | I7: 1594
A8: P. PIEDRA | B8: 81 | C8: 65 | D8: 93 | E8: 96 | F8: 94 | G8: 124 | H8: 157 | I8: 710
A9: MARINA | B9: 253 | C9: 305 | D9: 235 | E9: 321 | F9: 263 | G9: 340 | H9: 293 | I9: 2010
A10: TRUJILLO | B10: 409 | C10: 490 | D10: 399 | E10: 482 | F10: 420 | G10: 625 | H10: 558 | I10: 3383
A11: INDEPENDENCIA | B11: 344 | C11: 348 | D11: 331 | E11: 343 | F11: 268 | G11: 486 | H11: 311 | I11: 2431
A12: A.UGARTE | B12: 206 | C12: 227 | D12: 191 | E12: 213 | F12: 281 | G12: 321 | H12: 226 | I12: 1665
A13: PERSHING | B13: 86 | C13: 67 | D13: 63 | E13: 63 | F13: 81 | G13: 63 | H13: 77 | I13: 500
A14: CHORRILLOS | B14: 81 | C14: 131 | D14: 112 | E14: 61 | F14: 81 | G14: 52 | H14: 66 | I14: 584
A15: CALLAO | B15: 95 | C15: 105 | D15: 196 | E15: 190 | F15: 102 | G15: 105 | H15: 120 | I15: 913
A16: ARAMBURU | B16: 697 | C16: 393 | D16: 307 | E16: 349 | F16: 341 | G16: 808 | H16: 591 | I16: 3486
A17: ALIPIO | B17: 95 | C17: 98 | D17: 120 | E17: 117 | F17: 80 | G17: 95 | H17: 147 | I17: 752
A18: PLAZA UNION | B18: 82 | C18: 75 | D18: 83 | E18: 87 | F18: 81 | G18: 85 | H18: S/N | I18: 493
A19: JR UNION | B19: S/N | C19: S/N | D19: S/N | E19: S/N | F19: S/N | G19: S/N | H19: S/N | I19: S/N
A20: ARGENTINA | B20: 49 | C20: 67 | D20: 45 | E20: 44 | F20: 49 | G20: 70 | H20: 39 | I20: 363
A21: PUNO | B21: S/N | C21: S/N | D21: S/N | E21: S/N | F21: S/N | G21: S/N | H21: S/N | I21: S/N
H23: TOTAL | I23: =SUM(I5:I22) -> 20608
C25: CONTEO DE CLIENTES SEGURIDAD - 09 AL 15 DE MARZO 2026
A27: TIENDAS | B27: LUNES 9 | C27: MARTES 10 | D27: MIERCOLES 11 | E27: JUEVES 12 | F27: VIERNES 13 | G27: SABADO 14 | H27: DOMINGO 15 | I27: TOTAL
A28: AYACUCHO | B28: 357 | C28: 364 | D28: 383 | E28: 448 | F28: 379 | G28: 482 | H28: 341 | I28: 2754
A29: ANGAMOS | B29: 219 | C29: 217 | D29: 213 | E29: 188 | F29: 222 | G29: 245 | H29: 233 | I29: 1537
A30: TUMBES | B30: 68 | C30: 68 | D30: 56 | E30: 40 | F30: 60 | G30: 59 | H30: 130 | I30: 481
A31: EMANCIPACION | B31: 182 | C31: 179 | D31: 202 | E31: 195 | F31: 213 | G31: 260 | H31: 209 | I31: 1440
A32: P. PIEDRA | B32: 81 | C32: 66 | D32: 77 | E32: 86 | F32: 99 | G32: 121 | H32: 197 | I32: 727
A33: MARINA | B33: 254 | C33: 278 | D33: 240 | E33: 270 | F33: 314 | G33: 328 | H33: 353 | I33: 2037
A34: TRUJILLO | B34: 438 | C34: 481 | D34: 475 | E34: 501 | F34: 390 | G34: 567 | H34: 582 | I34: 3434
A35: INDEPENDENCIA | B35: 297 | C35: 324 | D35: D | E35: 290 | F35: 351 | G35: 364 | H35: 274 | I35: 1900
A36: A.UGARTE | B36: 250 | C36: 213 | D36: 262 | E36: 186 | F36: 258 | G36: 176 | H36: 188 | I36: 1533
A37: PERSHING | B37: 46 | C37: 436 | D37: 374 | E37: 438 | F37: 540 | G37: 542 | H37: 485 | I37: 2861
A38: CHORRILLOS | B38: 78 | C38: 84 | D38: 68 | E38: 76 | F38: 66 | G38: 86 | H38: 113 | I38: 571
A39: CALLAO | B39: 138 | C39: 170 | D39: 180 | E39: 193 | F39: 199 | G39: 201 | H39: 151 | I39: 1232
A40: ARAMBURU | B40: 340 | C40: 328 | D40: 349 | E40: 354 | F40: 444 | G40: 455 | H40: 428 | I40: 2698
A41: ALIPIO | B41: 66 | C41: 61 | D41: 95 | E41: 50 | F41: 136 | G41: 185 | H41: 144 | I41: 737
A42: PLAZA UNION | B42: 89 | C42: 105 | D42: 117 | E42: 113 | F42: 96 | G42: 103 | H42: 104 | I42: 727
A43: JR UNION | B43: 93 | C43: 88 | D43: 99 | E43: 73 | F43: 95 | G43: 87 | H43: 90 | I43: 625
A44: ARGENTINA | B44: 34 | C44: 53 | D44: 46 | E44: 52 | F44: 47 | G44: 85 | H44: 40 | I44: 357
...

Sheet ROBOS - FRUSTADOS
A1: C | C1: FRUSTRADOS | F1: REALIZADOS | I1: MONTO FRUSTRADO | J1: MONTO ROBADO | K1: FALTA
A2: ABRIL | B2: MARINA | C2: TEXTIL - DISNEY LACOSTE (2) S/34.90 + S/99.00 | D2: ABRIL | E2: MARINA | F2: TEXTIL - POLAR S/170.00 | H2: ABRIL | I2: 133.9 | J2: 170 | K2: 99 | M2: ABRIL | N2: RECUPERADO | O2: 1012.7
C3: OTROS - BILLETERA S/14.00 | E3: AYACUCHO | F3: CALZADO - ADIDAS (2) S/159.00 + S/169.00 | I3: 14 | J3: 328 | N3: PERDIDA | O3: 1286
C4: CALZADO - UNDER ARMOUR (1) S/139.00 | E4: EMANCIPACIÓN | F4: CALZADO - ECKKO (1) S/89.00 | I4: 139 | J4: 89 | N4: FALTA | O4: 99
B5: EMANCIPACIÓN | C5: TEXTIL - LACOSTE (1) S/79.00 | E5: PUENTE PIEDRA | F5: CALZADO - ADIDAS (1) S/249.00 | I5: 79 | J5: 249 | M5: MAYO | N5: RECUPERADO | O5: 1455.2
C6: CALZADO - MARCA (1) S/149.00 | E6: ANGAMOS | F6: TARJETA DE MEMORIA 128GH S/38.00 | I6: 149 | J6: 38 | N6: PERDIDA | O6: 637
B7: MARINA | C7: TEXTIL - POLO ARMANI (1) S/65.00 | E7: PUENTE PIEDRA | F7: CALZADO - ADIDAS (1) S/159.00 | I7: 65 | J7: 159
B8: INDEPENDENCIA | C8: TEXTIL - POLO BOSS (3) S/89.90 + S/79.00 + S/85.00 | E8: CALLAO | F8: CALZADO - ECKO S/109.00 | I8: 253.9 | J8: 109
B9: ALFONSO UGARTE | C9: CALZADO - ECKO S/89.00 | E9: MARINA | F9: OTROS - PERFUME DIAVOLO EDT (1) S/35.00 | I9: 89 | J9: 35
B10: MARINA | C10: TEXTIL LEGGING - ADIDAS (1) S/89.90 | E10: ANGAMOS | F10: CALZADO - ADIDAS (1) S/ 109.00 | I10: 89.9 | J10: 109
C11: 1012.7 | F11: 1286 | H11: MAYO | I11: 189 | J11: 69
I12: 499.5 | J12: 60
A13: MAYO | B13: AYACUCHO | C13: TEXTIL CASACA - NKG (1) S/189.00 | D13: MAYO | E13: ANGAMOS | F13: CALZADO - AVENGERS (1) S/69.00 | I13: 69.8 | J13: 389
B14: MARINA | C14: TEXTIL SHORT - NKG (5) S/499.50 | F14: OTROS - CREMA FACIAL (1) S/60.00 | I14: 99 | J14: 119
C15: TEXTIL POLO - QUICKSILVER (2) S/69.80 | E15: ALFONSO UGARTE | F15: CALZADO - NIKE (1) S/389.00 | I15: 198
C16: TEXTIL POLO - LACOSTE (1) S/99.00 | E16: ARGENTINA | F16: CALZADO - ADIDAS (1) S/119.00 | I16: 39.9
C17: TEXTIL POLO CAMISERO - LACOSTE (2) S/198.00 | I17: 149
C18: TEXTIL SHORT - EL CAPO (1) S/39.90 | I18: 81
B19: EMANCIPACIÓN | C19: CALZADO - ADIDAS (1) S/149.00 | F19: FALTA | I19: 130
C20: TEXTIL CASACA - MILK (1) S/81.00 | D20: ABRIL | E20: MARINA | F20: TEXTIL - LACOSTE (1) S/99.00
B21: ANGAMOS | C21: TEXTIL POLO - PSYCHO BUNNY (2) S/130.00 | F21: 99
A24: ROBOS POR SEMANA
A25: FECHA | D25: ESTADO | E25: AYACUCHO | F25: MARINA | G25: EMANCIPACIÓN | H25: PUENTE PIEDRA | I25: ANGAMOS | J25: INDEPENDENCIA | K25: CALLAO | L25: ALFONSO UGARTE | M25: ARGENTINA
A26: ABRIL SEMANA 1 | B26: 1 AL 7 | C26: 46113 | D26: FRUSTRADO | F26: TEXTIL - DISNEY LACOSTE (2) S/34.90 + S/99.00
D27: FRUSTRADO | F27: OTROS - BILLETERA S/14.00
C28: 46115 | D28: ROBO | F28: TEXTIL - POLAR S/170.00
A29: ABRIL SEMANA 2 | B29: 8 AL 14 | C29: 46120 | D29: ROBO | E29: CALZADO - ADIDAS (2) S/159.00 + S/169.00 | G29: CALZADO - ECKKO (1) S/89.00
C30: 46121 | D30: FRUSTRADO | F30: CALZADO - UNDER ARMOUR (1) S/139.00
C31: 46125 | D31: ROBO | H31: CALZADO - ADIDAS (1) S/249.00
D32: FALTA | F32: TEXTIL - LACOSTE (1) S/99.00
C33: 46126 | D33: ROBO | I33: TARJETA DE MEMORIA 128GH S/38.00
D34: FRUSTRADO | G34: TEXTIL - LACOSTE (1) S/79.00
A35: ABRIL SEMANA 3 | B35: 15 AL 21 | C35: 46128 | D35: FRUSTRADO | G35: CALZADO - MARCA (1) S/149.00
A36: ABRIL SEMANA 4 | B36: 22 AL 30 | C36: 46134 | D36: FRUSTRADO | F36: TEXTIL POLO - QUICKSILVER (2) S/69.80
D37: ROBO | H37: CALZADO - ADIDAS (1) S/159.00
C38: 46136 | D38: FRUSTRADO | J38: TEXTIL - POLO BOSS (3) S/89.90 + S/79.00 + S/85.00
D39: ROBO | K39: CALZADO - ECKO (1) S/109.00
C40: 46138 | D40: FRUSTRADO | L40: TEXTIL - POLO BOSS (3) S/89.90 + S/79.00 + S/85.00
D41: FRUSTRADO | F41: TEXTIL LEGGING - ADIDAS (1) S/89.90
D42: ROBO | F42: OTROS - PERFUME DIAVOLO EDT (1) S/35.00
...

Sheet ACTA DETENCIÓN
A1: ACTA DE DETENCIÓN POR HURTO
A2: ALMACÉN DE REMATES
A4: 1. INFORMACIÓN GENERAL
A5: Fecha: | D5: Hora:
A6: Lugar/Área:
A7: Reportado por:
A9: 2. DATOS COMPLETOS DEL DETENIDO
A10: Nombres y Apellidos:
A11: Documento de Identidad:
A12: Nacionalidad: | C12: Fecha Nac: | E12: Edad:
A13: Dirección:
A14: Barrio/Distrito: | C14: Teléfono:
A15: Contacto Familiar: | D15: Tel. Familiar:
A17: 3. DESCRIPCIÓN DE LOS HECHOS
A26: 4. DETALLE DE MERCANCÍA RECUPERADA
A27: Cant. | B27: Descripción / Marca | C27: Código / SKU | D27: Estado | E27: Valor
E37: TOTAL ESTIMADO | F37: =F28+F29+F30+F31+F32+F33+F34+F35+F36 -> 0
